2021-11-17 14:01:26,892 INFO    MainThread:362620 [wandb_setup.py:_flush():71] setting env: {}
2021-11-17 14:01:26,892 INFO    MainThread:362620 [wandb_setup.py:_flush():71] setting login settings: {}
2021-11-17 14:01:26,892 INFO    MainThread:362620 [wandb_init.py:_log_setup():357] Logging user logs to /media/hazemahmed/A/clothing_article_classification/wandb/run-20211117_140126-3q70gp5j/logs/debug.log
2021-11-17 14:01:26,892 INFO    MainThread:362620 [wandb_init.py:_log_setup():358] Logging internal logs to /media/hazemahmed/A/clothing_article_classification/wandb/run-20211117_140126-3q70gp5j/logs/debug-internal.log
2021-11-17 14:01:26,892 INFO    MainThread:362620 [wandb_init.py:init():390] calling init triggers
2021-11-17 14:01:26,893 INFO    MainThread:362620 [wandb_init.py:init():397] wandb.init called with sweep_config: {}
config: {}
2021-11-17 14:01:26,893 INFO    MainThread:362620 [wandb_init.py:init():435] starting backend
2021-11-17 14:01:26,893 INFO    MainThread:362620 [backend.py:_multiprocessing_setup():97] multiprocessing start_methods=fork,spawn,forkserver, using: spawn
2021-11-17 14:01:26,906 INFO    MainThread:362620 [backend.py:ensure_launched():199] starting backend process...
2021-11-17 14:01:26,916 INFO    MainThread:362620 [backend.py:ensure_launched():205] started backend process with pid: 362696
2021-11-17 14:01:26,918 INFO    MainThread:362620 [wandb_init.py:init():444] backend started and connected
2021-11-17 14:01:26,921 INFO    MainThread:362620 [wandb_init.py:init():503] updated telemetry
2021-11-17 14:01:26,947 INFO    MainThread:362620 [wandb_init.py:init():533] communicating current version
2021-11-17 14:01:27,701 INFO    MainThread:362620 [wandb_init.py:init():538] got version response 
2021-11-17 14:01:27,701 INFO    MainThread:362620 [wandb_init.py:init():548] communicating run to backend with 30 second timeout
2021-11-17 14:01:28,124 INFO    MainThread:362620 [wandb_init.py:init():576] starting run threads in backend
2021-11-17 14:01:29,749 INFO    MainThread:362620 [wandb_run.py:_console_start():1693] atexit reg
2021-11-17 14:01:29,750 INFO    MainThread:362620 [wandb_run.py:_redirect():1567] redirect: SettingsConsole.REDIRECT
2021-11-17 14:01:29,751 INFO    MainThread:362620 [wandb_run.py:_redirect():1572] Redirecting console.
2021-11-17 14:01:29,752 INFO    MainThread:362620 [wandb_run.py:_redirect():1628] Redirects installed.
2021-11-17 14:01:29,753 INFO    MainThread:362620 [wandb_init.py:init():603] run started, returning control to user process
2021-11-17 14:01:33,727 INFO    MainThread:362620 [wandb_watch.py:watch():43] Watching
2021-11-17 14:27:44,686 INFO    MainThread:362620 [wandb_run.py:_atexit_cleanup():1663] got exitcode: 255
2021-11-17 14:27:44,694 INFO    MainThread:362620 [wandb_run.py:_restore():1635] restore
2021-11-17 14:27:44,811 INFO    MainThread:362620 [wandb_run.py:_restore():1635] restore
2021-11-17 14:28:00,294 ERROR   MainThread:362620 [wandb_run.py:_atexit_cleanup():1681] Problem finishing run
Traceback (most recent call last):
  File "/home/hazemahmed/anaconda3/envs/torch_env/lib/python3.7/site-packages/wandb/sdk/wandb_run.py", line 1671, in _atexit_cleanup
    self._on_finish()
  File "/home/hazemahmed/anaconda3/envs/torch_env/lib/python3.7/site-packages/wandb/sdk/wandb_run.py", line 1817, in _on_finish
    self._console_stop()  # TODO: there's a race here with jupyter console logging
  File "/home/hazemahmed/anaconda3/envs/torch_env/lib/python3.7/site-packages/wandb/sdk/wandb_run.py", line 1711, in _console_stop
    self._restore()
  File "/home/hazemahmed/anaconda3/envs/torch_env/lib/python3.7/site-packages/wandb/sdk/wandb_run.py", line 1639, in _restore
    self._out_redir.uninstall()
  File "/home/hazemahmed/anaconda3/envs/torch_env/lib/python3.7/site-packages/wandb/sdk/lib/redirect.py", line 733, in uninstall
    time.sleep(1)
  File "/home/hazemahmed/anaconda3/envs/torch_env/lib/python3.7/site-packages/torch/utils/data/_utils/signal_handling.py", line 66, in handler
    _error_if_any_worker_fails()
RuntimeError: DataLoader worker (pid 379609) exited unexpectedly with exit code 1. Details are lost due to multiprocessing. Rerunning with num_workers=0 may give better error trace.
